{
 "cells": [
  {
   "cell_type": "markdown",
   "metadata": {},
   "source": [
    "# Python error handling\n",
    "\n",
    "## What will I learn?\n",
    "\n",
    "By the end of this module, you'll be able to:\n",
    "- Read and use error output from exceptions.\n",
    "- Properly handle exceptions.\n",
    "- Raise exceptions with useful error messages.\n",
    "- Use exceptions to control a program's flow.\n",
    "\n",
    "## What is the main objective?\n",
    "\n",
    "In this module, you'll learn about using exception output for debugging, how to catch and raise exceptions, and how to affect a program's logic when exceptions happen."
   ]
  },
  {
   "cell_type": "code",
   "execution_count": 1,
   "metadata": {},
   "outputs": [
    {
     "ename": "FileNotFoundError",
     "evalue": "[Errno 2] No such file or directory: '/path/to/mars.jpg'",
     "output_type": "error",
     "traceback": [
      "\u001b[0;31m---------------------------------------------------------------------------\u001b[0m",
      "\u001b[0;31mFileNotFoundError\u001b[0m                         Traceback (most recent call last)",
      "Cell \u001b[0;32mIn[1], line 4\u001b[0m\n\u001b[1;32m      1\u001b[0m \u001b[38;5;66;03m# Tracebacks\u001b[39;00m\n\u001b[1;32m      2\u001b[0m \u001b[38;5;66;03m# when there is an unhandled error, a traceback appears as the output\u001b[39;00m\n\u001b[0;32m----> 4\u001b[0m \u001b[38;5;28;43mopen\u001b[39;49m\u001b[43m(\u001b[49m\u001b[38;5;124;43m\"\u001b[39;49m\u001b[38;5;124;43m/path/to/mars.jpg\u001b[39;49m\u001b[38;5;124;43m\"\u001b[39;49m\u001b[43m)\u001b[49m\n",
      "File \u001b[0;32m~/workspace/beginner-python/.venv/lib/python3.8/site-packages/IPython/core/interactiveshell.py:284\u001b[0m, in \u001b[0;36m_modified_open\u001b[0;34m(file, *args, **kwargs)\u001b[0m\n\u001b[1;32m    277\u001b[0m \u001b[38;5;28;01mif\u001b[39;00m file \u001b[38;5;129;01min\u001b[39;00m {\u001b[38;5;241m0\u001b[39m, \u001b[38;5;241m1\u001b[39m, \u001b[38;5;241m2\u001b[39m}:\n\u001b[1;32m    278\u001b[0m     \u001b[38;5;28;01mraise\u001b[39;00m \u001b[38;5;167;01mValueError\u001b[39;00m(\n\u001b[1;32m    279\u001b[0m         \u001b[38;5;124mf\u001b[39m\u001b[38;5;124m\"\u001b[39m\u001b[38;5;124mIPython won\u001b[39m\u001b[38;5;124m'\u001b[39m\u001b[38;5;124mt let you open fd=\u001b[39m\u001b[38;5;132;01m{\u001b[39;00mfile\u001b[38;5;132;01m}\u001b[39;00m\u001b[38;5;124m by default \u001b[39m\u001b[38;5;124m\"\u001b[39m\n\u001b[1;32m    280\u001b[0m         \u001b[38;5;124m\"\u001b[39m\u001b[38;5;124mas it is likely to crash IPython. If you know what you are doing, \u001b[39m\u001b[38;5;124m\"\u001b[39m\n\u001b[1;32m    281\u001b[0m         \u001b[38;5;124m\"\u001b[39m\u001b[38;5;124myou can use builtins\u001b[39m\u001b[38;5;124m'\u001b[39m\u001b[38;5;124m open.\u001b[39m\u001b[38;5;124m\"\u001b[39m\n\u001b[1;32m    282\u001b[0m     )\n\u001b[0;32m--> 284\u001b[0m \u001b[38;5;28;01mreturn\u001b[39;00m \u001b[43mio_open\u001b[49m\u001b[43m(\u001b[49m\u001b[43mfile\u001b[49m\u001b[43m,\u001b[49m\u001b[43m \u001b[49m\u001b[38;5;241;43m*\u001b[39;49m\u001b[43margs\u001b[49m\u001b[43m,\u001b[49m\u001b[43m \u001b[49m\u001b[38;5;241;43m*\u001b[39;49m\u001b[38;5;241;43m*\u001b[39;49m\u001b[43mkwargs\u001b[49m\u001b[43m)\u001b[49m\n",
      "\u001b[0;31mFileNotFoundError\u001b[0m: [Errno 2] No such file or directory: '/path/to/mars.jpg'"
     ]
    }
   ],
   "source": [
    "# Tracebacks\n",
    "# when there is an unhandled error, a traceback appears as the output\n",
    "\n",
    "open(\"/path/to/mars.jpg\")  # error appears when trying to open an image that not exists\n",
    "\n",
    "# traceback shows\n",
    "# - All file paths involved, for every call to every function.\n",
    "# - Line numbers associated with every file path.\n",
    "# - The names of functions, methods, or classes involved in producing an exception.\n",
    "# - The name of the exception that was raised."
   ]
  },
  {
   "cell_type": "markdown",
   "metadata": {},
   "source": [
    "## run the following in a .py file to show the tracebacks\n",
    "\n",
    "```sh\n",
    "python session10/tracebacks.py\n",
    "```"
   ]
  },
  {
   "cell_type": "code",
   "execution_count": 2,
   "metadata": {},
   "outputs": [
    {
     "name": "stdout",
     "output_type": "stream",
     "text": [
      "Couldn't find the config.txt file!\n"
     ]
    }
   ],
   "source": [
    "# handle exceptions with try and except blocks\n",
    "\n",
    "# `try` keyword, you add code that has the potential to cause an exception. \n",
    "# Next, you add the `except` keyword along with the possible exception, \n",
    "# followed by any code that needs to run when that condition happens\n",
    "try:\n",
    "  open('config.txt')\n",
    "except FileNotFoundError:\n",
    "  print(\"Couldn't find the config.txt file!\")\n"
   ]
  },
  {
   "cell_type": "markdown",
   "metadata": {},
   "source": [
    "> Although a file that doesn't exist is common, it isn't the only error you might find. Invalid file permissions can prevent reading a file, even if the file exists\n",
    "\n",
    "```sh\n",
    "# Example showing `IsADirectoryError` error\n",
    "python session10/config.py\n",
    "\n",
    "# fix the issue by adding another except\n",
    "python session10/config2.py\n",
    "\n",
    "# handle errors in group by using parentheses in the except line\n",
    "python session10/config3.py\n",
    "\n",
    "# access the error attributes\n",
    "python session10/config4.py\n",
    "```"
   ]
  }
 ],
 "metadata": {
  "kernelspec": {
   "display_name": ".venv",
   "language": "python",
   "name": "python3"
  },
  "language_info": {
   "codemirror_mode": {
    "name": "ipython",
    "version": 3
   },
   "file_extension": ".py",
   "mimetype": "text/x-python",
   "name": "python",
   "nbconvert_exporter": "python",
   "pygments_lexer": "ipython3",
   "version": "3.8.18"
  }
 },
 "nbformat": 4,
 "nbformat_minor": 2
}
